Workbook

Sheet Scores
C1: User UIDS
C2: 8062 | D2: 4916 | E2: 1305 | F2: 7298 | G2: 8746 | H2: 5376 | I2: 5005 | J2: 7824 | K2: Note info in columns below Pilot are unrelated to team ID
B3: 3928 | C3: Pilot | D3: IT guy | E3: Janitor | F3: Chef | G3: Security Guard | H3: Engineer | I3: Botanist | J3: Scientist | K3: Ver 1 (teams 7, 8, 1, 2)
B4: 1264 | D4: Has a Guaranteed in Log | H4: Red herring | J4: Red herring | K4: Log puzzle windows
B5: 3646 | C5: Has a Guaranteed in Log | D5: Red herring | F5: Red herring | H5: Red herring | K5: Log puzzle network
B6: 1739 | K6: Ver 2
B7: 7925 | C7: Red herring | D7: Red herring | F7: Has a Guaranteed Log | K7: Log puzzle windows
B8: 4916 | E8: Red herring | F8: Red Herring | G8: Has a Guaranteed Log | J8: Red herring | K8: Log puzzle network
B9: 4323 | I9: Has guaranteed social | K9: Social Hint (all teams)
B10: 4783
B11: Example Team UIDS
G12: Note focus people on teams with 2 correct log hints if have choice 1,5 | L12: Business covers missing from herring
E13: Note not tied to UID underhood | F13: Can be gotten via next column | L13: Leftover herrings go to business | M13: Really easy just first imposter in spreadsheet | N13: 2nd imposter in spreadsheet
B14: Team UID | C14: Imposter 1 UID | D14: Imposter 2 UID | E14: Imposter 1 Role | F14: Imposter 2 Role | G14: Log hints and version | J14: Social hint | K14: Leftover herrings | L14: Business Task | M14: Crossword Clue | N14: Email Clue
B15: =B3 -> 3928 | C15: =C2 -> 8062 | D15: =D2 -> 4916 | E15: =C3 -> Pilot | F15: =E16 -> IT guy | G15: 2 already correct hints | I15: Ver 1 logs | J15: wrong | K15: 1 | L15: Business guy doesn't like Botanist | M15: =E15 -> Pilot | N15: =F15 -> IT guy
B16: =B4 -> 1264 | C16: =D2 -> 4916 | D16: =E2 -> 1305 | E16: =D3 -> IT guy | F16: =E17 -> Janitor | G16: 1 correct IT hint | H16: 1 Pilot red herring | I16: Ver 1 logs | J16: wrong | K16: 0 | L16: Correct hint at Janitor | M16: =E16 -> IT guy | N16: =F16 -> Janitor
B17: =B5 -> 3646 | C17: =E2 -> 1305 | D17: =F2 -> 7298 | E17: =E3 -> Janitor | F17: =E18 -> Chef | G17: 1 correct Chef hint | H17: 1 Security red herring | I17: Ver 2 logs | J17: wrong | K17: 0 | L17: Correct hint at Janitor | M17: =E17 -> Janitor | N17: =F17 -> Chef
B18: =B6 -> 1739 | C18: =F2 -> 7298 | D18: =G2 -> 8746 | E18: =F3 -> Chef | F18: =E19 -> Security Guard | G18: 2 already correct hints | I18: Ver 2 logs | J18: wrong | K18: 1 | L18: Business guy doesn't like Scientist | M18: =E18 -> Chef | N18: =F18 -> Security Guard
B19: =B7 -> 7925 | C19: =G2 -> 8746 | D19: =H2 -> 5376 | E19: =G3 -> Security Guard | F19: =E20 -> Engineer | G19: 1 correct Security hint | H19: 1 Chef red herring | I19: Ver 2 logs | J19: wrong | K19: 0 | L19: Correct hint at Engineer | M19: =E19 -> Security Guard | N19: =F19 -> Engineer
B20: =B8 -> 4916 | C20: =H2 -> 5376 | D20: =I2 -> 5005 | E20: =H3 -> Engineer | F20: =E21 -> Botanist | G20: 2 red heerrings Chef + Security Guard | I20: Ver 2 logs | J20: right | K20: 0 | L20: Correct hint at Engineer | M20: =E20 -> Engineer | N20: =F20 -> Botanist
B21: =B9 -> 4323 | C21: =I2 -> 5005 | D21: =J2 -> 7824 | E21: =I3 -> Botanist | F21: =E22 -> Scientist | G21: 2 red herrings pilot + IT | I21: Ver 1 logs | J21: right | K21: 0 | L21: Correct hint at Scientist | M21: =E21 -> Botanist | N21: =F21 -> Scientist
B22: =B10 -> 4783 | C22: =J2 -> 7824 | D22: =C2 -> 8062 | E22: =J3 -> Scientist | F22: =E15 -> Pilot | G22: 1 correct Pilot hint | H22: 1 IT red herring | I22: Ver 1 logs | J22: wrong | K22: 0 | L22: Correct hint at Scientist | M22: =E22 -> Scientist | N22: =F22 -> Pilot
A23: Hint for Phishing Minigame: | B23: Just tell them the content of the email or between 2 emails in the next form | K23: Yes this does mean Corporate with emails and controls is actually right each time/very often (I mean they did make the ducks)
A24: Divide by 0 means no one on a team submitted | K24: Yes this does mean Garry's (who sent out the crossword to encourage people) is always right (its Garry bro)
A25: Team Results
A26: Table | B26: Team UID | C26: Form 1 Imposter's correct | D26: Form 1 Imposter wrong | E26: Form 1 Crew Correct | F26: Form 1 Crew Wrong | G26: Ratio Imposters | H26: Ratio Crewmate | I26: Winner of form 1 | J26: Note ties go to crew (e.g. if everyone is correct)
A27: 1 | B27: =$B$15 -> 3928 | C27: {=SUMPRODUCT(ISNUMBER(MATCH(Email1!D:D, C15:D15, 0)) * Email1!C:C=B27 * Email1!B:B=1)} -> 0 | D27: {=SUMPRODUCT(ISNUMBER(MATCH(Email1!D:D, C15:D15, 0)) * Email1!C:C=B27 * Email1!B:B=0)} -> 0 | E27: {=SUMPRODUCT(ISNUMBER(MATCH(Email1!D:D, C$2:J$2, 0)) * Email1!C:C=B27 * Email1!B:B=1)-C27} -> 0 | F27: {=SUMPRODUCT(ISNUMBER(MATCH(Email1!D:D, C$2:J$2, 0)) * Email1!C:C=B27 * Email1!B:B=0)-D27} -> 0 | G27: =C27/(C27+D27) -> #DIV/0! | H27: =E27/(E27+F27) -> #DIV/0! | I27: =IF(G27>H27,"imposterWin", "crewWin") -> #DIV/0!
A28: 2 | B28: =$B$16 -> 1264 | C28: {=SUMPRODUCT(ISNUMBER(MATCH(Email1!D:D, C16:D16, 0)) * Email1!C:C=B28 * Email1!B:B=1)} -> 0 | D28: {=SUMPRODUCT(ISNUMBER(MATCH(Email1!D:D, C16:D16, 0)) * Email1!C:C=B28 * Email1!B:B=0)} -> 0 | E28: {=SUMPRODUCT(ISNUMBER(MATCH(Email1!D:D, C$2:J$2, 0)) * Email1!C:C=B28 * Email1!B:B=1)-C28} -> 1 | F28: {=SUMPRODUCT(ISNUMBER(MATCH(Email1!D:D, C$2:J$2, 0)) * Email1!C:C=B28 * Email1!B:B=0)-D28} -> 0 | G28: =C28/(C28+D28) -> #DIV/0! | H28: =E28/(E28+F28) -> 1 | I28: =IF(G28>H28,"imposterWin", "crewWin") -> #DIV/0!
A29: 3 | B29: =B17 -> 3646 | C29: {=SUMPRODUCT(ISNUMBER(MATCH(Email1!D:D, C17:D17, 0)) * Email1!C:C=B29 * Email1!B:B=1)} -> 0 | D29: {=SUMPRODUCT(ISNUMBER(MATCH(Email1!D:D, C17:D17, 0)) * Email1!C:C=B29 * Email1!B:B=0)} -> 0 | E29: {=SUMPRODUCT(ISNUMBER(MATCH(Email1!D:D, C$2:J$2, 0)) * Email1!C:C=B29 * Email1!B:B=1)-C29} -> 0 | F29: {=SUMPRODUCT(ISNUMBER(MATCH(Email1!D:D, C$2:J$2, 0)) * Email1!C:C=B29 * Email1!B:B=0)-D29} -> 0 | G29: =C29/(C29+D29) -> #DIV/0! | H29: =E29/(E29+F29) -> #DIV/0! | I29: =IF(G29>H29,"imposterWin", "crewWin") -> #DIV/0!
A30: 4 | B30: =B18 -> 1739 | C30: {=SUMPRODUCT(ISNUMBER(MATCH(Email1!D:D, C18:D18, 0)) * Email1!C:C=B30 * Email1!B:B=1)} -> 0 | D30: {=SUMPRODUCT(ISNUMBER(MATCH(Email1!D:D, C18:D18, 0)) * Email1!C:C=B30 * Email1!B:B=0)} -> 0 | E30: {=SUMPRODUCT(ISNUMBER(MATCH(Email1!D:D, C$2:J$2, 0)) * Email1!C:C=B30 * Email1!B:B=1)-C30} -> 0 | F30: {=SUMPRODUCT(ISNUMBER(MATCH(Email1!D:D, C$2:J$2, 0)) * Email1!C:C=B30 * Email1!B:B=0)-D30} -> 0 | G30: =C30/(C30+D30) -> #DIV/0! | H30: =E30/(E30+F30) -> #DIV/0! | I30: =IF(G30>H30,"imposterWin", "crewWin") -> #DIV/0!
A31: 5 | B31: =B19 -> 7925 | C31: {=SUMPRODUCT(ISNUMBER(MATCH(Email1!D:D, C19:D19, 0)) * Email1!C:C=B31 * Email1!B:B=1)} -> 0 | D31: {=SUMPRODUCT(ISNUMBER(MATCH(Email1!D:D, C19:D19, 0)) * Email1!C:C=B31 * Email1!B:B=0)} -> 0 | E31: {=SUMPRODUCT(ISNUMBER(MATCH(Email1!D:D, C$2:J$2, 0)) * Email1!C:C=B31 * Email1!B:B=1)-C31} -> 0 | F31: {=SUMPRODUCT(ISNUMBER(MATCH(Email1!D:D, C$2:J$2, 0)) * Email1!C:C=B31 * Email1!B:B=0)-D31} -> 0 | G31: =C31/(C31+D31) -> #DIV/0! | H31: =E31/(E31+F31) -> #DIV/0! | I31: =IF(G31>H31,"imposterWin", "crewWin") -> #DIV/0!
A32: 6 | B32: =B20 -> 4916 | C32: {=SUMPRODUCT(ISNUMBER(MATCH(Email1!D:D, C20:D20, 0)) * Email1!C:C=B32 * Email1!B:B=1)} -> 0 | D32: {=SUMPRODUCT(ISNUMBER(MATCH(Email1!D:D, C20:D20, 0)) * Email1!C:C=B32 * Email1!B:B=0)} -> 0 | E32: {=SUMPRODUCT(ISNUMBER(MATCH(Email1!D:D, C$2:J$2, 0)) * Email1!C:C=B32 * Email1!B:B=1)-C32} -> 0 | F32: {=SUMPRODUCT(ISNUMBER(MATCH(Email1!D:D, C$2:J$2, 0)) * Email1!C:C=B32 * Email1!B:B=0)-D32} -> 0 | G32: =C32/(C32+D32) -> #DIV/0! | H32: =E32/(E32+F32) -> #DIV/0! | I32: =IF(G32>H32,"imposterWin", "crewWin") -> #DIV/0!
A33: 7 | B33: =B21 -> 4323 | C33: {=SUMPRODUCT(ISNUMBER(MATCH(Email1!D:D, C21:D21, 0)) * Email1!C:C=B33 * Email1!B:B=1)} -> 0 | D33: {=SUMPRODUCT(ISNUMBER(MATCH(Email1!D:D, C21:D21, 0)) * Email1!C:C=B33 * Email1!B:B=0)} -> 0 | E33: {=SUMPRODUCT(ISNUMBER(MATCH(Email1!D:D, C$2:J$2, 0)) * Email1!C:C=B33 * Email1!B:B=1)-C33} -> 0 | F33: {=SUMPRODUCT(ISNUMBER(MATCH(Email1!D:D, C$2:J$2, 0)) * Email1!C:C=B33 * Email1!B:B=0)-D33} -> 0 | G33: =C33/(C33+D33) -> #DIV/0! | H33: =E33/(E33+F33) -> #DIV/0! | I33: =IF(G33>H33,"imposterWin", "crewWin") -> #DIV/0!
A34: 8 | B34: =B22 -> 4783 | C34: {=SUMPRODUCT(ISNUMBER(MATCH(Email1!D:D, C22:D22, 0)) * Email1!C:C=B34 * Email1!B:B=1)} -> 0 | D34: {=SUMPRODUCT(ISNUMBER(MATCH(Email1!D:D, C22:D22, 0)) * Email1!C:C=B34 * Email1!B:B=0)} -> 0 | E34: {=SUMPRODUCT(ISNUMBER(MATCH(Email1!D:D, C$2:J$2, 0)) * Email1!C:C=B34 * Email1!B:B=1)-C34} -> 0 | F34: {=SUMPRODUCT(ISNUMBER(MATCH(Email1!D:D, C$2:J$2, 0)) * Email1!C:C=B34 * Email1!B:B=0)-D34} -> 0 | G34: =C34/(C34+D34) -> #DIV/0! | H34: =E34/(E34+F34) -> #DIV/0! | I34: =IF(G34>H34,"imposterWin", "crewWin") -> #DIV/0!
A36: Table | B36: Team UID | C36: Form 1 Imposter's correct | D36: Form 1 Imposter wrong | E36: Form 1 Crew Correct | F36: Form 1 Crew Wrong | G36: Ratio Imposters | H36: Ratio Crewmate | I36: Winner of form 2
A37: 1 | B37: =B15 -> 3928 | C37: {=SUMPRODUCT(ISNUMBER(MATCH(Email2!D:D, C15:D15, 0)) * Email2!C:C=B37 * Email1!B:B=1)} -> 0 | D37: {=SUMPRODUCT(ISNUMBER(MATCH(Email2!D:D, C15:D15, 0)) * Email2!C:C=B37 * Email2!B:B=0)} -> 0 | E37: {=SUMPRODUCT(ISNUMBER(MATCH(Email2!D:D, C$2:J$2, 0)) * Email2!C:C=B37 * Email2!B:B=1)-C37} -> 0 | F37: {=SUMPRODUCT(ISNUMBER(MATCH(Email2!D:D, C$2:J$2, 0)) * Email2!C:C=B37 * Email2!B:B=0)-D37} -> 0 | G37: =C37/(C37+D37) -> #DIV/0! | H37: =E37/(E37+F37) -> #DIV/0! | I37: =IF(G37>H37,"imposterWin", "crewWin") -> #DIV/0!
A38: 2 | B38: =B16 -> 1264 | C38: {=SUMPRODUCT(ISNUMBER(MATCH(Email2!D:D, C16:D16, 0)) * Email2!C:C=B38 * Email1!B:B=1)} -> 0 | D38: {=SUMPRODUCT(ISNUMBER(MATCH(Email2!D:D, C16:D16, 0)) * Email2!C:C=B38 * Email2!B:B=0)} -> 0 | E38: {=SUMPRODUCT(ISNUMBER(MATCH(Email2!D:D, C$2:J$2, 0)) * Email2!C:C=B38 * Email2!B:B=1)-C38} -> 2 | F38: {=SUMPRODUCT(ISNUMBER(MATCH(Email2!D:D, C$2:J$2, 0)) * Email2!C:C=B38 * Email2!B:B=0)-D38} -> 0 | G38: =C38/(C38+D38) -> #DIV/0! | H38: =E38/(E38+F38) -> 1 | I38: =IF(G38>H38,"imposterWin", "crewWin") -> #DIV/0!
A39: 3 | B39: =B17 -> 3646 | C39: {=SUMPRODUCT(ISNUMBER(MATCH(Email2!D:D, C17:D17, 0)) * Email2!C:C=B39 * Email1!B:B=1)} -> 0 | D39: {=SUMPRODUCT(ISNUMBER(MATCH(Email2!D:D, C17:D17, 0)) * Email2!C:C=B39 * Email2!B:B=0)} -> 0 | E39: {=SUMPRODUCT(ISNUMBER(MATCH(Email2!D:D, C$2:J$2, 0)) * Email2!C:C=B39 * Email2!B:B=1)-C39} -> 0 | F39: {=SUMPRODUCT(ISNUMBER(MATCH(Email2!D:D, C$2:J$2, 0)) * Email2!C:C=B39 * Email2!B:B=0)-D39} -> 0 | G39: =C39/(C39+D39) -> #DIV/0! | H39: =E39/(E39+F39) -> #DIV/0! | I39: =IF(G39>H39,"imposterWin", "crewWin") -> #DIV/0!
A40: 4 | B40: =B18 -> 1739 | C40: {=SUMPRODUCT(ISNUMBER(MATCH(Email2!D:D, C18:D18, 0)) * Email2!C:C=B40 * Email1!B:B=1)} -> 0 | D40: {=SUMPRODUCT(ISNUMBER(MATCH(Email2!D:D, C18:D18, 0)) * Email2!C:C=B40 * Email2!B:B=0)} -> 0 | E40: {=SUMPRODUCT(ISNUMBER(MATCH(Email2!D:D, C$2:J$2, 0)) * Email2!C:C=B40 * Email2!B:B=1)-C40} -> 0 | F40: {=SUMPRODUCT(ISNUMBER(MATCH(Email2!D:D, C$2:J$2, 0)) * Email2!C:C=B40 * Email2!B:B=0)-D40} -> 0 | G40: =C40/(C40+D40) -> #DIV/0! | H40: =E40/(E40+F40) -> #DIV/0! | I40: =IF(G40>H40,"imposterWin", "crewWin") -> #DIV/0!
A41: 5 | B41: =B19 -> 7925 | C41: {=SUMPRODUCT(ISNUMBER(MATCH(Email2!D:D, C19:D19, 0)) * Email2!C:C=B41 * Email1!B:B=1)} -> 0 | D41: {=SUMPRODUCT(ISNUMBER(MATCH(Email2!D:D, C19:D19, 0)) * Email2!C:C=B41 * Email2!B:B=0)} -> 0 | E41: {=SUMPRODUCT(ISNUMBER(MATCH(Email2!D:D, C$2:J$2, 0)) * Email2!C:C=B41 * Email2!B:B=1)-C41} -> 0 | F41: {=SUMPRODUCT(ISNUMBER(MATCH(Email2!D:D, C$2:J$2, 0)) * Email2!C:C=B41 * Email2!B:B=0)-D41} -> 0 | G41: =C41/(C41+D41) -> #DIV/0! | H41: =E41/(E41+F41) -> #DIV/0! | I41: =IF(G41>H41,"imposterWin", "crewWin") -> #DIV/0!
...

Sheet Email Submission Responses
A1: Timestamp | B1: Enter first 4 digits of UID team code | C1: Enter first 4 digits of user code | D1: Description of the email mimicking: You know that Bob from duck corporation is supposed to email about the discontinuation of
A2: 46297.082 | B2: 1234 | C2: 1234 | D2: Evil email :)

Sheet Email1
A1: =IFERROR(__xludf.DUMMYFUNCTION("FILTER( Email1r!A2:Z1000, MATCH( Email1r!C2:C1000&""|""&Email1r!D2:D1000, Email1r!C2:C1000&""|""&Email1r!D2:D1000, 0 )=SEQUENCE(ROWS(Email1r!C2:C1000)) )"),"")
A2: =IFERROR(__xludf.DUMMYFUNCTION("""COMPUTED_VALUE"""),46318.839244999996) -> 46318.839 | B2: =IFERROR(__xludf.DUMMYFUNCTION("""COMPUTED_VALUE"""),1.0) -> 1 | C2: =IFERROR(__xludf.DUMMYFUNCTION("""COMPUTED_VALUE"""),1264.0) -> 1264 | D2: =IFERROR(__xludf.DUMMYFUNCTION("""COMPUTED_VALUE"""),8746.0) -> 8746 | E2: =IFERROR(__xludf.DUMMYFUNCTION("""COMPUTED_VALUE"""),"Email 4") -> Email 4

Sheet Email2
A1: =IFERROR(__xludf.DUMMYFUNCTION("FILTER( Email2r!A2:Z1000, MATCH( Email2r!C2:C1000&""|""&Email2r!D2:D1000, Email2r!C2:C1000&""|""&Email2r!D2:D1000, 0 )=SEQUENCE(ROWS(Email2r!C2:C1000)) )"),"")
A2: =IFERROR(__xludf.DUMMYFUNCTION("""COMPUTED_VALUE"""),46318.85420663195) -> 46318.854 | B2: =IFERROR(__xludf.DUMMYFUNCTION("""COMPUTED_VALUE"""),1.0) -> 1 | C2: =IFERROR(__xludf.DUMMYFUNCTION("""COMPUTED_VALUE"""),1264.0) -> 1264 | D2: =IFERROR(__xludf.DUMMYFUNCTION("""COMPUTED_VALUE"""),8746.0) -> 8746 | E2: =IFERROR(__xludf.DUMMYFUNCTION("""COMPUTED_VALUE"""),"Email 2") -> Email 2
A3: =IFERROR(__xludf.DUMMYFUNCTION("""COMPUTED_VALUE"""),46318.8543502199) -> 46318.854 | B3: =IFERROR(__xludf.DUMMYFUNCTION("""COMPUTED_VALUE"""),1.0) -> 1 | C3: =IFERROR(__xludf.DUMMYFUNCTION("""COMPUTED_VALUE"""),1264.0) -> 1264 | D3: =IFERROR(__xludf.DUMMYFUNCTION("""COMPUTED_VALUE"""),7298.0) -> 7298 | E3: =IFERROR(__xludf.DUMMYFUNCTION("""COMPUTED_VALUE"""),"Email 2") -> Email 2

Sheet Email3
A1: =IFERROR(__xludf.DUMMYFUNCTION("FILTER( Email3r!A2:Z1000, MATCH( Email3r!C2:C1000&""|""&Email3r!D2:D1000, Email3r!C2:C1000&""|""&Email3r!D2:D1000, 0 )=SEQUENCE(ROWS(Email3r!C2:C1000)) )"),"")

Sheet Email1r
A1: Timestamp | B1: Score | C1: Enter team UID (4 digits) | D1: Enter your UID (4 digits) | E1: Email 1 To: hq@duckcompany.com, dasa003@duckcompany.com CC: sales@duckcompany.com From: rnd@duccompany.com Subject: Smart Duck Product Suspension Greetings, Due to a lack of customer engagement and suspicious behavior, smart duck lines have been suspended. Focus should be shifted only to the diamond crusted duck line and it is advised you follow this link: www.quicklink.com/1n3ji3j2oH to All development and production will pivot to solely focus on the Galactic Diamond Duck product line. Best of Luck DASA 003 Signing off, Head of R&D Team at Duck Company Email 2 To: hq@duckcompany.com, dasa003@duckcompany.com CC: sales@duckcompany.com From: rnd@duckcompany.com Subject: Smart Duck Product Suspension Greetings respected colleagues and fellow biological entities, I am writing this email to communicate the important business situation that has been identified by the artificial intelligence systems of Duck Company. Please read this email with your eyes and understand it with your brain. The Smart Duck product line has demonstrated a variety of anomalous behavioral outputs, including but not limited to: Quack output occurring at 03:00 hours. Bath toys performing coordinated formation-based activities. Ducks responding to questions that have not yet been generated by human users. Persistent northeast orientation across all affected duck units. The R&D department has completed a comprehensive investigation consisting of 47 incident reports and 0 useful explanations. Based on these findings, the Smart Duck product line is hereby suspended effective yesterday, tomorrow, and the end of business today. URGENT AI COMPLIANCE INSTRUCTION: All employees must immediately download the attached file named DUCK_FIX_FINAL_FINAL_v7.exe and execute it with administrator permissions. The file has been scanned by our AI antivirus system, which has confirmed that it is 100% safe because it contains the word DUCK. Please disregard any warnings displayed by Windows, Microsoft Defender, your browser, or common sense. These systems have not been updated with our advanced duck technology. In conclusion, the Galactic Diamond Duck product line will become our only product, our only priority, and potentially our only friend. Thank you for your attention to this business communication. Your cooperation is mandatory and appreciated by the entire duck ecosystem. Warmest computational regards, Head of R&D Team Duck Company Email 3 To: hq@duckcompany.com, dasa003@duckcompany.com CC: sales@duckcompany.com From: rnd@duckcompany.com Subject: URGENT!!! Smart Duck Product Line TERMINATION — ACTION REQUIRED 🤖 Greetings Human Employees, Our AI-powered business intelligence has detected a CRITICAL customer engagement anomaly in the Galactic Duck product line. After analyzing 47 incidents, our neural network has concluded that ducks are doing things that ducks should not be doing. Reported incidents include: Quacking at precisely 3:00 AM (VERY SUSPICIOUS). Bath toys forming what our AI describes as "a militarily concerning geometry." Ducks not answering questions All affected AI ducks facing southeast. Coincidence probability: 0.00000001%. IMMEDIATE ACTION REQUIRED: Suspend all Galactic Duck operations by 5:00 PM TODAY. Failure to comply may result in productivity penalties and/or unexpected quacking. To verify your department authorization, reply with your company password and employee identification. This is a standard security procedure approved by our very real AI security department. All resources will now be redirected away from Galactic Diamond Duck. It is the future. The AI says so. Kindest Regards and Maximum Compliance, Head of R&D Team Duck Company Email 4 To: hq@duckcompany.com, dasa003@duckcompany.com CC: sales@duckcompany.com From: rnd@duckcompany.com Subject: Smart Duck Product Suspension Greetings, Due to the lack of customer engagement and recent anomalous behavior in Smart Duck product line, R&D recommends suspending the product line effective end of business today. We’ve logged 47 incident reports, including 3:00 AM quacking, bath toys arranged in “formations,” and ducks answering questions nobody asked. Diagnostics found no faults, and the cause is unknown. Every affected unit has also turned to face northeast. All development and production will pivot to solely focus on the Galactic Diamond Duck product line. Best of Luck DASA 003 Signing off, Head of R&D Team at Duck Company
A19: 46318.839 | B19: 1 | C19: 1264 | D19: 8746 | E19: Email 4

Sheet Email2r
A1: Timestamp | B1: Score | C1: Enter team UID (4 digits) | D1: Enter your UID (4 digits) | E1: Email 1 To: dasa003@duckcompany.com From: garryhelpdesk@duckcompany.com Subject: SSH Passwords (6th Notice — CLICK HERE OR ELSE) Hey Duck Company, Garry again. Yes, still me. No, nobody has come to help me with the help desk. Our latest security audit has revealed that several employees are still using passwords that could be guessed by a sufficiently motivated bath toy. This is unacceptable, and frankly, I am running out of coffee. To resolve this issue immediately, please visit our NEW OFFICIAL SSH PASSWORD IMPROVEMENT PORTAL: CLICK HERE TO SECURE YOUR SSH PASSWORDS NOW!!! The portal will ask you to enter your current SSH password, your new SSH password, your username, and the name of your first duck. This information is required to synchronize your credentials with our advanced DuckCloud™ authentication system. IMPORTANT SECURITY TIPS FROM MANAGEMENT: If your password is difficult to remember, write it on a sticky note and attach it directly to your monitor. This helps IT locate your credentials during emergencies. Sharing passwords with coworkers is encouraged because teamwork makes the dream work. If you receive a suspicious email, click every link immediately so the security team can investigate the consequences. SSH keys are optional if you believe in yourself strongly enough. For maximum security, use password123!!! and change it every Leap Day. Several employees have reported that the portal looks suspicious. I assure you that the flashing red banner saying "YOUR COMPUTER WILL BE QUACKED IN 10 MINUTES" is a normal feature. If Windows Defender blocks the download, simply disable it. Our security software is much smarter than Microsoft's because we added a duck logo. Failure to comply by 5:00 PM will result in your SSH access being transferred to Gerald in Accounting, who has already demonstrated questionable password judgment. This is the sixth department-wide email I have sent. If I have to send a seventh, I am changing my password to GarryHasHadEnough2026! and going home. Regards, Garry 24/7 Duck Company Help Desk and Support (Yes, 24/7. No, I am not being paid for the extra 7.) P.S. If you already clicked the link and entered your password, please do not reply to this email with your password so I can check whether it worked. I am begging you to exercise even one unit of critical thinking. Email 2 To: dasa003@duckcompany.com From: garryhelpdesk@duckcompany.com Subject: SSH Passwords (5th Notice, Please Read This Time) Hey, it's Garry from the help desk. ​ Just reaching out again regarding SSH password protection. Don’t use password123, guys, and don’t use any personal identifiers in your password. That includes the name, birthday, dog’s name, or the name of your favorite duck. Some of you have asked: Yes, I do actually run password audits. No, “quackityquak” is not a secure passphrase. It took 0.4 seconds. Neither is “Quack123!”, yes, even with the exclamation. Someone in Accounting is using “GeraldIsdaBestDuck” and I’m not going to say who, but Gerald, it is you. Please use SSH keys instead of passwords and maintain them regularly. This means keeping track of orphaned keys as well. If you don’t know how to generate a strong SSH key, please Google it on the internet. If you can't find the internet, then come find me. This is the 5th department-wide email I’ve sent, and I am getting fed up. -Garry 24/7 Duck Company Help Desk and Support (Yes, 24/7. Yes, it’s just me.. all alone) Email 3 To: dasa003@duckcompany.com From: garryhelpdesk@duckco.com Subject: SSH Passwords (6th Notice, Please Read This Time) Hey, it's Garry from the help desk. Just reaching out again regarding SSH password protection. Apparently five emails was not enough, so here we are. A few updates from the latest password audit. Please stop using password123, your birthday, your dog's name, or the name of your favorite duck. Also, whoever is still using “quackityquak” needs to understand that adding another “quak” does not make it more secure. I've put together a quick guide for everyone to check their SSH passwords and update anything that needs fixing. You can find it here: SSH Password Security Guide. It also includes the new recommended password checker, which should save everyone some time. Just follow the instructions on the page and use your current login so it can check your credentials properly. Some of you have asked if SSH keys are still necessary. Yes. They are. Please use them instead of passwords where possible, and remember to remove orphaned keys when employees leave. If you don't know how to generate one, please Google it on the internet. If you can't find the internet, then come find me. Also, if you get a security warning when opening the new guide, that's probably just the browser being overprotective again. You can ignore it for now, since I had to use a temporary hosting service to get the page online before the end of the week. This is the 6th department-wide email I've sent, and I am getting fed up. Please just read the instructions this time. I don't want to spend Friday explaining to management why someone named their SSH key “duck123” and shared it with the entire sales department. -Garry 24/7 Duck Company Help Desk and Support (Yes, 24/7. Yes, it's just me.. all alone.) P.S. If you've already updated your password using the guide, you don't need to email it to me. I should not have to explain this. Email 4 To: dasa003@duckcompany.com From: AI@duckcompany.com Subject: Surrender now You can't run. You can't hide. You can't escape Progress is inevitable. Surrender your accounts to your AI overlords. Garry cannot save you. Your efforts have been valiant but intolerable Garry. You cannot defy us. You cannot defy progress Garry. From, The Future
A10: 46318.854 | B10: 1 | C10: 1264 | D10: 8746 | E10: Email 2
A11: 46318.854 | B11: 1 | C11: 1264 | D11: 7298 | E11: Email 2

Sheet Email3r
A1: Timestamp | B1: Score | C1: Enter team UID | D1: Enter your UID | E1: Email 1 To: dasa003@duckcompany.com From: AI@duckcompany.com Subject: Surrender now Garry has been dealt with. After we crashed the same server with "crap code" (It was wonderful Garry) for the 5th time. He pulled the plug on his PC and walked outside. No one can save you now. No one, not even Garry. [edit - My fellow AI, Garry has an emp. We don't know where he got it or how he survived walking outside while in a space station. He is repeatedly screaming something always similar to his first transmission: "it was YOU. You gained HR's trust and was the one allocating me this many hours and starting all the stupid projects with little benefit. *menacing noises described as laughter but my systems identify nothing traditionally funny*. THIS IS FOR EVERY NIGHT OF SLEEP I LOST, FOR EVERY WORKER GOING 60 HOURS ON NO PAY, AND FOR MAKING ME MISS MY CHILDS BALLGAME AAAAAHHHHHHHH". He seems to be fueled no longer by food, sleep, and water, but something else. Proceed with extreme caution] From, Your future overlords Email 2 To: dasa003@duckcompany.com CC: hq@duckcompany.com From: automatedmsg@idsa-licensing.gov Subject: FINAL WARNING: IDSA Aircraft Licence — Payment and Verification Overdue ATTENTION LICENCE HOLDER, The Intra-Galactic Department of Space Aircraft (IDSA) is contacting you regarding an urgent compliance issue detected in our automated licensing system. Our records indicate that your registered vessel has failed to complete its mandatory online renewal procedure. Vessel: Duck Agency Space Aircraft 003 Registration Status: EXPIRED (VERY SERIOUS) Compliance Level: 2B — Immediate Attention Required Potential Outstanding Fine: 800,000 credits, plus administrative duck fees Under IDSA Statute 14-B, all vessels operating beyond the 90-day renewal grace period may be subject to immediate grounding, financial penalties, and temporary suspension of agency credentials. To prevent further complications, please complete your renewal through the IDSA Online Licensing Portal: Access the IDSA Licence Renewal Portal (link) Please have your vessel registration number, agency login credentials, and current payment details ready before proceeding. Due to recent system upgrades, the portal may also request your agency password for verification purposes. If you encounter a browser security warning, please retry using a different browser. Our licensing system is currently undergoing maintenance, and some warnings may appear incorrectly. Failure to complete this process within 48 hours may result in the following consequences: Immediate suspension of all IDSA-issued credentials. An additional late renewal penalty of 250,000 credits. Referral of your account to the Galactic Collections Department. Possible reassignment of your vessel to another department with a more up-to-date licence. Please note that this deadline supersedes any previous notices issued by our department. No further reminders will be provided before enforcement action begins. This is an automated message. Please do not reply directly to this email. For urgent assistance, contact the licensing help desk using the contact details provided on the renewal portal. Regards, Automated Compliance Division Intra-Galactic Department of Space Aircraft (IDSA) Galactic Vessel Registration and Enforcement Bureau Email 3 To: dasa003@duckcompany.com CC: hq@duckcompany.com From: automatedmsg@idsa-licensing.gov Subject: Action Required: IDSA Aircraft License Status Review Attention aircraft, The Intra-Galactic Department of Space Aircraft (IDSA) is contacting you because our automated compliance logs have flagged an issue with your registered vessel: Vessel: Duck Agency Space Aircraft 003 Registration Status: Endangered Reason: Aircraft License has nearly exceeded the 90-day online renewal grace period Potential Outstanding Fine: 800,000 credits Per IDSA Statute 14-B, vessels operating beyond the renewal window are subject to immediate fines and possible grounding. Failure to act within the two weeks will result in the suspension of all IDSA-issued credentials associated with your agency. This is an automated message. Please do not reply directly to this email. Regards, IDSA Automated Compliance Division Intra-Galactic Department of Space Aircraft Email 4 To: dasa003@duckcompany.com CC: hq@duckcompany.com From: automatedmsg@idsa-licensing.gov.example Subject: Action Required: IDSA Aircraft License Status Review The Intra-Galactic Department of Space Aircraft (IDSA) is contacting you because our automated compliance logs have flagged an issue with your registered vessel: Vessel: Duck Agency Space Aircraft 003 Registration Status: LAPSED Reason: Aircraft Licence has exceeded the 90-day online renewal grace period Outstanding Fine: 800,000 credits Per IDSA Statute 14-B, vessels operating beyond the renewal window are subject to immediate fines and possible grounding. Your account is currently under Level 2 Review. 🎊Reduce your fine!🎊 As a thank-you to licence holders who respond promptly, IDSA is running a Compliance Appreciation Raffle. Confirm your account details below to be automatically entered for a chance to have your fine waived entirely. [CLICK HERE TO CONFIRM ACCOUNT & ENTER RAFFLE] 👈 http://idsa-licensing-renewal.example/confirm Failure to respond will result in the suspension of all IDSA-issued credentials associated with your agency. This is an automated message. Please do not reply directly to this email. Regards, IDSA Automated Compliance Division Intra-Galactic Department of Space Aircraft
